Workbook

Sheet UI TOTALS
D2: S1 | E2: S2 | F2: EXTRA | G2: JSS | H2: OTHER/CG | I2: T5/CG | J2: TOTALS | K2: JSS% | L2: JSS+Team | M2: Notes
C3: UIHTML | D3: =UIHTML!E34 -> 11 | E3: =UIHTML!F34 -> 16 | F3: =UIHTML!G34 -> 14 | G3: =SUM(D3:F3)-H3 -> 36 | H3: 5 | I3: 8 | J3: =SUM(G3:I3) -> 49 | K3: =G3/J3 -> 0.73469388 | L3: =(G3+I3)/J3 -> 0.89795918 | M3: Pravani Built SSO Pages
C4: UIREACT | D4: =UIREACT!E37 -> 0 | E4: =UIREACT!F37 -> 25 | F4: =UIREACT!G37 -> 8 | G4: 9 | H4: 16 | I4: 9 | J4: =SUM(G4:I4) -> 34 | K4: =G4/J4 -> 0.26470588 | L4: =(G4+I4)/J4 -> 0.52941176 | M4: Lily Did S1 Design EndToEnd
C5: UIIONIC | D5: 0 | E5: 0 | F5: =UIIONIC!G14 -> 11 | G5: 11 | H5: 0 | I5: 0 | J5: =SUM(G5:I5) -> 11 | K5: =G5/J5 -> 1 | L5: =(G5+I5)/J5 -> 1 | M5: Slave to HTML Front-End
C6: UIMANAGER | D6: =UIMANAGEROTHER!E27 -> 2 | E6: =UIMANAGEROTHER!F27 -> 0 | F6: =UIMANAGEROTHER!G27 -> 22 | G6: 18 | H6: 0 | I6: 0 | J6: =SUM(G6:I6) -> 18 | K6: =G6/J6 -> 1 | L6: =(G6+I6)/J6 -> 1 | M6: Manager Required For S2
D7: 13 | E7: =E4+E3 -> 41 | F7: =SUM(F3:F6) -> 55 | G7: =SUM(G3:G6) -> 74 | H7: =SUM(H3:H4) -> 21 | I7: =SUM(I3:I4) -> 17 | J7: =SUM(G7:I7) -> 112
C9: BACKOFFICE - EPS | D9: 5 | E9: 12 | F9: =163-17 -> 146 | G9: 164 | H9: 1 | I9: 0 | J9: 165 | K9: =G9/J9 -> 0.99393939 | L9: =(G9+I9)/J9 -> 0.99393939 | M9: Kaleb Wrote Auth, 33 Tables * Avg of 5 EPs
C10: DTOs | D10: 0 | E10: 2 | F10: 8 | G10: 10 | H10: 0 | I10: 0 | J10: 10 | K10: =J10/G10 -> 1 | L10: =(G10+I10)/J10 -> 1
E11: =SUM(E9:E10) -> 14 | F11: =SUM(F9:F10) -> 154 | G11: =SUM(G9:G10) -> 174 | H11: =SUM(H9:H10) -> 1 | I11: =SUM(I9:I10) -> 0 | J11: =SUM(J9:J10) -> 175 | K11: =G11/J11 -> 0.99428571 | L11: =(G11+I11)/J11 -> 0.99428571
C13: UNITS OF WORK | G13: =G11+G7 -> 248 | H13: =H11+H7 -> 22 | I13: =I11+I7 -> 17 | J13: =J11+J7 -> 287 | K13: =G13/J13 -> 0.8641115 | L13: =(G13+I13)/J13 -> 0.92334495 | M13: As Designed with Combined JSS & LCG
C16: Minimalistic Units of Work | H16: After S1 the CGUI was produced and it dramatically impacted the design. It allowed for a more compact backoffice.
C17: React | E17: 25 | H17: This means that most of the S1 work for a Meets Target was extraneous.
C18: DTOs | E18: 2 | H18: I believe however my toolset is significantly in aggregate better than the requirement.
C19: Services | E19: 2
C20: EPs | E20: 5 | H20: ParkReviews, Payments, Bookings + Pipeline North, Pipeline South
C21: Tables/Models | E21: 14 | H21: Parks, ParkReviews, Users, Payments, Bookings, Cards, Logs
C22: Contexts | E22: 1
C23: Data Architecture | E23: 5
C24: Project Plan/Slides | E24: 10
C25: UG Teams with 4 People in Minimalism | E25: =SUM(E16:E24) -> 64
E26: =E25/4 -> 16 | F26: Units of Work Each
C28: JSS v AVG | D28: 248 | E28: 16 | F28: =D28/E28 -> 15.5 | G28: I was asked to work 15X more than the avg student in the class in a class I have already taken and got a B+
G29: I was impacted in 2 other classes, and I lost 1500.00 in Scholarship money, offset by grad contract.

Sheet ControllersLogicByType
C2: TECHNOLOGY CONTRIBUTION | D2: REQUIRED | E2: TYPE1 | F2: TYPE2 | G2: DISCUSSION | H2: ORIGIN | I2: DEVELOPER | J2: TEAM | K2: CODETYPE
B3: 1 | C3: Adminlog | D3: NO | E3: SECURITY | H3: NEW | I3: JSS | J3: 547G-T5 | K3: REST-ENDPOINT-NEW
B4: =B3+1 -> 2 | C4: Apilog | D4: NO | E4: SECURITY | H4: NEW | I4: JSS | J4: 547G-T5 | K4: REST-ENDPOINT-NEW
B5: =B4+1 -> 3 | C5: Booking | D5: 1 | E5: SALES | H5: NEW | I5: JSS | J5: 547G-T5 | K5: REST-ENDPOINT-NEW
B6: =B5+1 -> 4 | C6: Card | D6: 1 | E6: BUSINESS | H6: NEW | I6: JSS | J6: 547G-T5 | K6: REST-ENDPOINT-NEW
B7: =B6+1 -> 5 | C7: Cart | D7: 1 | E7: BUSINESS | H7: NEW | I7: JSS | J7: 547G-T5 | K7: REST-ENDPOINT-NEW
B8: =B7+1 -> 6 | C8: Cartitem | D8: 1 | E8: BUSINESS | H8: NEW | I8: JSS | J8: 547G-T5 | K8: REST-ENDPOINT-NEW
B9: =B8+1 -> 7 | C9: CartMaster | D9: NO | E9: BUSINESS | H9: NEW | I9: JSS | J9: 547G-T5 | K9: REST-ENDPOINT-NEW
B10: =B9+1 -> 8 | C10: Notify(Email-Sendmail) | D10: EXTRAC | E10: OPS | H10: NEW | I10: JSS | J10: 547G-T5 | K10: REST-ENDPOINT-NEW
B11: =B10+1 -> 9 | C11: Noctech | D11: NO | E11: OPS | H11: NEW | I11: JSS | J11: 547G-T5 | K11: REST-ENDPOINT-NEW
B12: =B11+1 -> 10 | C12: Park | D12: 1 | E12: SALES | H12: NEW | I12: JSS | J12: 547G-T5 | K12: REST-ENDPOINT-NEW
B13: =B12+1 -> 11 | C13: ParkReview | D13: 1 | E13: SALES | H13: NEW | I13: JSS | J13: 547G-T5 | K13: REST-ENDPOINT-NEW
B14: =B13+1 -> 12 | C14: Payment | D14: 1 | E14: BUSINESS | H14: NEW | I14: JSS | J14: 547G-T5 | K14: REST-ENDPOINT-NEW
B15: =B14+1 -> 13 | C15: SalesCatalogue | D15: EXTRAC | E15: BUSINESS | H15: NEW | I15: JSS | J15: 547G-T5 | K15: REST-ENDPOINT-NEW
B16: =B15+1 -> 14 | C16: Superuserlog | D16: NO | E16: SECURITY | H16: NEW | I16: JSS | J16: 547G-T5 | K16: REST-ENDPOINT-NEW | L16: =COUNT(B3:B16) -> 14 | N16: =L16/$M$36 -> 0.42424242
B17: =B16+1 -> 15 | C17: Batch | D17: NO | E17: ERPEXTENSIONS | F17: UTILITY | G17: GSPORTALv2 | H17: MODS from V1 to (V2) | I17: JSS | J17: GS->MIX547G | K17: REST-PORTTOSQLITE
B18: =B17+1 -> 16 | C18: Batchtype | D18: NO | E18: ERPEXTENSIONS | F18: UTILITY | G18: GSPORTALv2 | H18: MODS from V1 to (V2) | I18: JSS | J18: GS->MIX547G | K18: REST-PORTTOSQLITE
B19: =B18+1 -> 17 | C19: Company | D19: NO | E19: BUSINESS | F19: VERSION UPGRADE | G19: GSPORTALv2 | H19: MODS from V1 to (V2) | I19: JSS | J19: GS->MIX547G | K19: REST-PORTTOSQLITE
B20: =B19+1 -> 18 | C20: Customer | D20: NO | E20: BUSINESS | F20: VERSION UPGRADE | G20: GSPORTALv2 | H20: MODS from V1 to (V2) | I20: JSS | J20: GS->MIX547G | K20: REST-PORTTOSQLITE
B21: =B20+1 -> 19 | C21: Employee | D21: NO | E21: SSO | F21: VERSION UPGRADE | G21: GSPORTALv2 | H21: MODS from V1 to (V2) | I21: JSS | J21: GS->MIX547G | K21: REST-PORTTOSQLITE
B22: =B21+1 -> 20 | C22: File | D22: NO | E22: SSO | F22: VERSION UPGRADE | G22: GSPORTALv2 | H22: MODS from V1 to (V2) | I22: JSS | J22: GS->MIX547G | K22: REST-PORTTOSQLITE
B23: =B22+1 -> 21 | C23: FileOps | D23: NO | E23: SSO | F23: VERSION UPGRADE | G23: GSPORTALv2 | H23: MODS from V1 to (V2) | I23: JSS | J23: GS->MIX547G | K23: REST-PORTTOSQLITE
B24: =B23+1 -> 22 | C24: User | D24: 1 | E24: SSO | F24: VERSION UPGRADE | G24: GSPORTALv2 | H24: MODS from V1 to (V2) | I24: JSS | J24: GS->MIX547G | K24: REST-PORTTOSQLITE | L24: =COUNT(B17:B24) -> 8 | N24: =L24/$M$36 -> 0.24242424
B25: =B24+1 -> 23 | C25: Auth | D25: NO | E25: SSO | F25: SECURITY | G25: GSPORTALv1 | H25: SPRING25 | I25: K.BAUGH | J25: GHOST SQUAD | K25: REST-PORTTOSQLITE
B26: =B25+1 -> 24 | C26: Profile | D26: NO | E26: SSO | G26: GSPORTALv1 | H26: SPRING25 | I26: JSS | J26: GHOST SQUAD | K26: REST-PORTTOSQLITE
B27: =B26+1 -> 25 | C27: Sessionlog | D27: NO | E27: SECURITY | G27: GSPORTALv1 | H27: SPRING25 | I27: JSS | J27: GHOST SQUAD | K27: REST-PORTTOSQLITE
B28: =B27+1 -> 26 | C28: Site | D28: NO | E28: BUSINESS | G28: GSPORTALv1 | H28: SPRING25 | I28: JSS | J28: GHOST SQUAD | K28: REST-PORTTOSQLITE
B29: =B28+1 -> 27 | C29: Learnlog | D29: NO | E29: TRAINING | G29: GSPORTALv1 | H29: SPRING25 | I29: JSS | J29: GHOST SQUAD | K29: REST-PORTTOSQLITE
B30: =B29+1 -> 28 | C30: Useraction | D30: NO | E30: SECURITY | G30: GSPORTALv1 | H30: SPRING25 | I30: JSS | J30: GHOST SQUAD | K30: REST-PORTTOSQLITE
B31: =B30+1 -> 29 | C31: Usergroup | D31: NO | E31: SSO | G31: GSPORTALv1 | H31: SPRING25 | I31: JSS | J31: GHOST SQUAD | K31: REST-PORTTOSQLITE
B32: =B31+1 -> 30 | C32: Userhelp | D32: NO | E32: OPS | G32: GSPORTALv1 | H32: SPRING25 | I32: JSS | J32: GHOST SQUAD | K32: REST-PORTTOSQLITE
B33: =B32+1 -> 31 | C33: Userlog | D33: NO | E33: SECURITY | G33: GSPORTALv1 | H33: SPRING25 | I33: JSS | J33: GHOST SQUAD | K33: REST-PORTTOSQLITE
B34: =B33+1 -> 32 | C34: Userprofile | D34: EXTRAC | E34: SSO | G34: GSPORTALv1 | H34: SPRING25 | I34: JSS | J34: GHOST SQUAD | K34: REST-PORTTOSQLITE
B35: =B34+1 -> 33 | C35: Usersession | D35: NO | E35: SSO | G35: GSPORTALv1 | H35: SPRING25 | I35: JSS | J35: GHOST SQUAD | K35: REST-PORTTOSQLITE | L35: =COUNT(B25:B35) -> 11 | N35: =L35/M36 -> 0.33333333 | P35: =O36/M36 -> 0.57575758
B36: CONSULTING AND DESIGN CONTRIBUTIONS | M36: =COUNT(B3:B35) -> 33 | O36: =L35+L24 -> 19
B37: 1 | C37: Business Logic - Dirtbike Project - Base Design and Program Plan | E37: SALES | F37: PROGRAM | H37: NEW | I37: CAPGEMENI CONSULTING | J37: GC-SOUTHEAST | K37: BUSINESSLOGIC
B38: =B37+1 -> 2 | C38: Business Logic - Greenville Associates Consulting - Park Rescope | E38: SALES | F38: PROGRAM | H38: NEW | I38: GREENVILLEASSOCIATES | J38: GA-CAROLINAS | K38: BUSINESSLOGIC
B39: =B38+1 -> 3 | C39: Business Logic - Greenville Associates Consulting - Park Visualizations | E39: SALES | F39: PROGRAM | H39: NEW | I39: GREENVILLEASSOCIATES | J39: GA-CAROLINAS | K39: BUSINESSLOGIC
B40: =B39+1 -> 4 | C40: Business Logic - Greenville Associates Consulting - Public Web to Mobile Arch | E40: SALES | F40: PROGRAM | H40: NEW | I40: GREENVILLEASSOCIATES | J40: GA-CAROLINAS | K40: BUSINESSLOGIC
B41: =B40+1 -> 5 | C41: Business Logic - Greenville Associates Consulting - SSO SQL Restrictions | E41: SALES | F41: PROGRAM | H41: NEW | I41: GREENVILLEASSOCIATES | J41: GA-CAROLINAS | K41: BUSINESSLOGIC | M41: REQUIRED Eps
...

Sheet UIHTML
C2: TECHNOLOGY CONTRIBUTION | D2: Date | E2: REQUIREDS1 | F2: REQUIREDS2 | G2: RUBRICEXTRA | H2: TYPE1 | I2: TYPE2 | J2: DISCUSSION | K2: ORIGIN | L2: DEVELOPER | M2: TEAM | N2: CODETYPE
B3: 1 | C3: book5.html | D3: 2025/11/06 - 17:43:05 | E3: 1 | F3: 1 | H3: SALES | L3: JSS | M3: 547G-T5 | N3: HTMLUI
B4: =B3+1 -> 2 | C4: cart5.html | D4: 2025/11/01 - 21:48:08 | E4: 1 | F4: 1 | H4: SALES | L4: JSS | M4: 547G-T5 | N4: HTMLUI
B5: =B4+1 -> 3 | C5: cartcancel.html | D5: 2025/10/25 - 04:53:01 | E5: 1 | F5: 1 | H5: CARE | L5: JSS | M5: 547G-T5 | N5: HTMLUI
B6: =B5+1 -> 4 | C6: cartdetail.html | D6: 2025/11/01 - 23:23:19 | E6: 1 | F6: 1 | H6: SALES | L6: JSS | M6: 547G-T5 | N6: HTMLUI
B7: =B6+1 -> 5 | C7: cartdetail2b.html | D7: 2025/10/24 - 16:56:51 | E7: 1 | F7: 1 | H7: SALES | L7: JSS | M7: 547G-T5 | N7: HTMLUI
B8: =B7+1 -> 6 | C8: cartreview.html | D8: 2025/11/06 - 17:43:32 | E8: 1 | F8: 1 | H8: SALES | L8: JSS | M8: 547G-T5 | N8: HTMLUI
B9: =B8+1 -> 7 | C9: employeemaint.html | D9: 2025/11/06 - 15:26:18 | E9: NO | F9: EC | G9: 1 | H9: PARKMGR | L9: JSS | M9: 547G-T5 | N9: HTMLUI
B10: =B9+1 -> 8 | C10: findpark.html | D10: 2025/10/25 - 04:54:02 | E10: NO | F10: NO | G10: 1 | H10: SALES | L10: JSS | M10: 547G-T5 | N10: HTMLUI
B11: =B20+1 -> 10 | C11: mybookings5.html | D11: 2025/11/02 - 00:46:47 | E11: NO | F11: 1 | H11: SALES | L11: JSS | M11: 547G-T5 | N11: HTMLUI
B12: =B11+1 -> 11 | C12: parkmaint.html | D12: 2025/10/26 - 21:39:05 | E12: NO | F12: 1 | H12: PARKMGR | L12: JSS | M12: 547G-T5 | N12: HTMLUI
B13: =B12+1 -> 12 | C13: parks5.html | D13: 2025/10/26 - 20:28:47 | E13: 1 | F13: 1 | H13: SALES | L13: JSS | M13: 547G-T5 | N13: HTMLUI
B14: =B13+1 -> 13 | C14: parksreview5.html | D14: 2025/10/25 - 04:42:41 | E14: 1 | F14: 1 | H14: CARE | L14: JSS | M14: 547G-T5 | N14: HTMLUI
B15: =B14+1 -> 14 | C15: parkvisualizations.html | D15: 2025/10/28 - 16:49:21 | E15: NO | F15: NO | G15: 1 | H15: SALES | L15: JSS | M15: 547G-T5 | N15: HTMLUI
B16: =B15+1 -> 15 | C16: payments8.html | D16: 2025/11/02 - 22:56:35 | E16: 1 | F16: 1 | H16: CARE | L16: JSS | M16: 547G-T5 | N16: HTMLUI
B17: =B16+1 -> 16 | C17: paynow2.html | D17: 2025/11/02 - 00:42:28 | E17: 1 | F17: 1 | H17: CARE | L17: JSS | M17: 547G-T5 | N17: HTMLUI
B18: =B17+1 -> 17 | C18: picturewall.html | D18: 2025/10/26 - 17:36:57 | E18: NO | F18: NO | G18: 1 | H18: SALES | L18: JSS | M18: 547G-T5 | N18: HTMLUI | O18: =COUNT(B3:B18) -> 16
B19: =B18+1 -> 18 | C19: securitycenter.html | D19: 2025/10/26 - 17:36:57 | E19: NO | F19: NO | G19: 1 | H19: SECURITY | L19: JSS | M19: 547G-T5 | N19: HTMLUI
B20: =B10+1 -> 9 | C20: login.html | D20: 2025/11/01 - 17:21:42 | E20: NO | F20: 1 | H20: SSO | L20: JSS | M20: 547G-T5 | N20: HTMLUI
B21: =B19+1 -> 19 | C21: adminhome.html | D21: 2025/11/01 - 17:55:49 | E21: NO | F21: 1 | G21: 1 | H21: PARKMGR | L21: JSS | M21: GS->MIX547G | N21: HTMLUI
B22: =B21+1 -> 20 | C22: help.html | D22: 2025/11/01 - 17:55:49 | E22: NO | F22: NO | H22: OPS | L22: JSS | M22: GS->MIX547G | N22: HTMLUI
B23: =B22+1 -> 21 | C23: about.html | D23: 2025/11/01 - 17:55:49 | E23: NO | F23: NO | H23: PROJECT | L23: JSS | M23: GS->MIX547G | N23: HTMLUI
B24: =B23+1 -> 22 | C24: utilities.html | D24: 2025/11/01 - 17:55:49 | E24: NO | F24: NO | H24: PROJECT | L24: JSS | M24: GS->MIX547G | N24: HTMLUI
B25: =B24+1 -> 23 | C25: loginstatus.html | D25: 2025/11/01 - 17:55:49 | E25: NO | F25: NO | H25: SSO | L25: JSS | M25: GS->MIX547G | N25: HTMLUI
B26: =B25+1 -> 24 | C26: manager.html | D26: 2025/10/25 - 04:42:59 | E26: NO | F26: 1 | G26: 1 | H26: PARKMGR | L26: JSS | M26: GS->MIX547G | N26: HTMLUI | O26: 3
B27: =B26+1 -> 25 | C27: adminerror.html | D27: 2025/11/01 - 01:26:52 | E27: NO | F27: NO | G27: 1 | H27: SECURITY | L27: JSS | M27: GHOST SQUAD | N27: HTMLUI
B28: =B27+1 -> 26 | C28: forgot.html | D28: 2025/11/01 - 01:26:52 | E28: NO | F28: NO | G28: 1 | H28: SSO | L28: PRANAVI | M28: GHOST SQUAD | N28: HTMLUI
B29: =B27+1 -> 26 | C29: userprofile | D29: 2025/11/01 - 01:26:52 | E29: NO | F29: NO | G29: 1 | H29: SSO | L29: CAROLINA/JOHN/SAMBIT | M29: GHOST SQUAD | N29: HTMLUI
B30: =B28+1 -> 27 | C30: register.html | D30: 2025/11/01 - 01:26:52 | E30: NO | F30: NO | G30: 1 | H30: SSO | L30: PRANAVI | M30: GHOST SQUAD | N30: HTMLUI
B31: =B30+1 -> 28 | C31: passwordreset.html | D31: 2025/11/01 - 01:26:52 | E31: NO | F31: NO | G31: 1 | H31: SSO | L31: PRANAVI | M31: GHOST SQUAD | N31: HTMLUI
B32: =B31+1 -> 29 | C32: index.html | D32: 2025/11/06 - 15:20:43 | E32: 1 | F32: 1 | G32: 1 | H32: SALES | L32: JSS | M32: GHOST SQUAD | N32: HTMLUI
B33: =B32+1 -> 30 | C33: loginerror.html | D33: 2025/10/31 - 17:01:28 | E33: NO | F33: NO | G33: 1 | H33: PARKMGR | L33: JSS | M33: GHOST SQUAD | N33: HTMLUI | O33: 3
B34: =COUNT(B3:B33) -> 31 | E34: =COUNT(E3:E33) -> 11 | F34: =COUNT(F3:F33) -> 16 | G34: =SUM(G3:G33) -> 14
C36: TECHNOLOGY CONTRIBUTION | D36: Date | E36: REQUIREDS1 | F36: REQUIREDS2 | G36: RUBRICEXTRA | H36: TYPE1 | I36: TYPE2 | J36: DISCUSSION | K36: ORIGIN | L36: DEVELOPER | M36: TEAM | N36: CODETYPE
B37: 1 | C37: dropdown.css | D37: 2025/11/01 - 21:48:08 | E37: 1 | F37: 1 | H37: SALES | L37: JSS | M37: 567JSS | N37: HTMLUI | O37: 1
B38: 2 | C38: seeding data parks -sc | D38: 2025/10/25 - 04:53:01 | E38: 1 | F38: 1 | H38: OPS | L38: JSS | M38: 547G-T5 | N38: ORIGINAL DATA
B39: 3 | C39: seeding data parks -other states | D39: 2025/10/25 - 04:53:01 | E39: 1 | F39: 1 | H39: OPS | L39: JSS | M39: 547G-T5 | N39: ORIGINAL DATA
B40: 4 | C40: seeding data parks -us national | D40: 2025/10/25 - 04:53:01 | E40: 1 | F40: 1 | H40: OPS | L40: JSS | M40: 547G-T5 | N40: ORIGINAL DATA
B41: 5 | C41: seeding data parks -mexico | D41: 2025/10/25 - 04:53:01 | E41: 1 | F41: 1 | H41: OPS | L41: JSS | M41: 547G-T5 | N41: ORIGINAL DATA
B42: 6 | C42: seeding data parks -canada | D42: 2025/10/25 - 04:53:01 | E42: 1 | F42: 1 | H42: OPS | L42: JSS | M42: 547G-T5 | N42: ORIGINAL DATA | O42: =SUM(E37:E42) -> 6
...

Sheet UIREACT
C2: TECHNOLOGY CONTRIBUTION | D2: Date | E2: REQUIREDS1 | F2: REQUIREDS2 | G2: RUBRICEXTRA | H2: TYPE1 | I2: TYPE2 | J2: DISCUSSION | K2: ORIGIN | L2: DEVELOPER | M2: TEAM | N2: CODETYPE
B3: 1 | C3: allreviews.tsx | D3: 46001 | E3: NO | F3: 0 | G3: 1 | H3: SALES | K3: NEW | L3: JSS | M3: 547G-T5 | N3: REACT
B4: =B3+1 -> 2 | C4: home2.tsx | D4: 46001 | E4: NO | F4: 0 | G4: 1 | H4: SALES | K4: NEW | L4: JSS | M4: 547G-T5 | N4: REACT
B5: =B4+1 -> 3 | C5: details2.tsx | D5: 46001 | E5: NO | F5: 0 | G5: 1 | H5: SALES | K5: NEW | L5: JSS | M5: 547G-T5 | N5: REACT
B6: =B5+1 -> 4 | C6: logout.tsx | D6: 46001 | E6: NO | F6: 0 | G6: 1 | H6: SSO | K6: NEW | L6: JSS | M6: 547G-T5 | N6: REACT
B7: =B6+1 -> 5 | C7: login.tsx | D7: 46001 | E7: NO | F7: 0 | G7: 1 | H7: SSO | K7: NEW | L7: JSS | M7: 547G-T5 | N7: REACT
B8: =B7+1 -> 6 | C8: register.tsx | D8: 46001 | E8: NO | F8: 0 | G8: 1 | H8: SSO | K8: NEW | L8: JSS | M8: 547G-T5 | N8: REACT
B9: =B8+1 -> 7 | C9: reservations.tsx | D9: 46001 | E9: NO | F9: 0 | G9: 1 | H9: PARKMGR | K9: NEW | L9: JSS | M9: 547G-T5 | N9: REACT
B10: =B9+1 -> 8 | C10: securityadmin.tsx | D10: 46001 | E10: NO | F10: 0 | G10: 1 | H10: SECURITY | K10: NEW | L10: JSS | M10: 547G-T5 | N10: REACT
B11: =B20+1 -> 10 | C11: welcome.tsx | D11: 46001 | E11: NO | F11: 0 | H11: SALES | K11: NEW | L11: JSS | M11: 547G-T5 | N11: REACT
B12: =B11+1 -> 11 | C12: bookingService.tsx | D12: 46001 | E12: NO | F12: 1 | H12: SALES | K12: MOD | L12: JSS | M12: 547G-T5/CG JOINT | N12: REACT
B13: =B12+1 -> 12 | C13: parkService.tsx | D13: 46001 | E13: NO | F13: 1 | H13: SALES | K13: MOD | L13: JSS | M13: 547G-T5/CG JOINT | N13: REACT
B14: =B13+1 -> 13 | C14: cartService.tsx | D14: 46001 | E14: NO | F14: 1 | H14: SALES | K14: MOD | L14: JSS | M14: 547G-T5/CG JOINT | N14: REACT
B15: =B14+1 -> 14 | C15: parkcard.tsx (Mod for Reviews) | D15: 46001 | E15: NO | F15: 1 | H15: SALES | K15: MOD | L15: JSS | M15: 547G-T5/CG JOINT | N15: REACT
B16: =B15+1 -> 15 | C16: homebar.tsx(Rebuild) | D16: 46001 | E16: NO | F16: 1 | H16: SALES | K16: MOD | L16: JSS | M16: 547G-T5/CG JOINT | N16: REACT
B17: =B16+1 -> 16 | C17: footer.tsx(Rebuild) | D17: 46001 | E17: NO | F17: 1 | H17: SALES | K17: MOD | L17: JSS | M17: 547G-T5/CG JOINT | N17: REACT
B18: =B17+1 -> 17 | C18: payment.tsx(Rebuild) | D18: 46001 | E18: NO | F18: 1 | H18: SALES | K18: MOD | L18: JSS | M18: 547G-T5/CG JOINT | N18: REACT | O18: =COUNT(B3:B18) -> 16
B19: =B18+1 -> 18 | C19: cartCard(Style) | D19: 46001 | E19: NO | F19: 1 | H19: SALES | K19: MOD | L19: JSS | M19: 547G-T5/CG JOINT | N19: REACT
B20: =B10+1 -> 9 | C20: heroContent(Style) | D20: 46001 | E20: NO | F20: 1 | H20: SALES | K20: MOD | L20: JSS | M20: 547G-T5/CG JOINT | N20: REACT
B21: =B19+1 -> 19 | C21: bookRide | D21: 45971 | E21: NO | F21: 1 | H21: BUSINESS | L21: LILY/KYLE | M21: CAPGEMENI | N21: REACT
B22: =B21+1 -> 20 | C22: cartDetails | D22: 45971 | E22: NO | F22: 1 | H22: BUSINESS | L22: LILY/KYLE | M22: CAPGEMENI | N22: REACT
B23: =B22+1 -> 21 | C23: details.tsx | D23: 45971 | E23: NO | F23: 1 | H23: BUSINESS | L23: LILY/KYLE | M23: CAPGEMENI | N23: REACT
B24: =B23+1 -> 22 | C24: featuredparks.tsx | D24: 45971 | E24: NO | F24: 1 | H24: BUSINESS | L24: LILY/KYLE | M24: CAPGEMENI | N24: REACT
B25: =B24+1 -> 23 | C25: heroContent | D25: 45971 | E25: NO | F25: 1 | H25: BUSINESS | L25: LILY/KYLE | M25: CAPGEMENI | N25: REACT
B26: =B25+1 -> 24 | C26: app.tsx | D26: 45971 | E26: NO | F26: 1 | H26: BUSINESS | L26: LILY/KYLE | M26: CAPGEMENI | N26: REACT
B27: =B26+1 -> 25 | C27: search | D27: 45971 | E27: NO | F27: 1 | H27: BUSINESS | L27: LILY/KYLE | M27: CAPGEMENI | N27: REACT
B28: =B27+1 -> 26 | C28: reviewCard | D28: 45971 | E28: NO | F28: 1 | H28: BUSINESS | L28: LILY/KYLE | M28: CAPGEMENI | N28: REACT
B29: =B28+1 -> 27 | C29: parkcard.tsx (Core) | D29: 45971 | E29: NO | F29: 1 | H29: BUSINESS | L29: LILY/KYLE | M29: CAPGEMENI | N29: REACT | O29: 3
B30: =B29+1 -> 28 | C30: Cart | D30: 45971 | E30: NO | F30: 1 | H30: BUSINESS | L30: LILY/KYLE | M30: CAPGEMENI | N30: REACT
B31: =B30+1 -> 29 | C31: Home | D31: 45971 | E31: NO | F31: 1 | H31: BUSINESS | L31: LILY/KYLE | M31: CAPGEMENI | N31: REACT
B32: =B30+1 -> 29 | C32: ParkDetails | D32: 45971 | E32: NO | F32: 1 | H32: BUSINESS | L32: LILY/KYLE | M32: CAPGEMENI | N32: REACT
B33: =B31+1 -> 30 | C33: Models-Cart | D33: 45971 | E33: NO | F33: 1 | H33: BUSINESS | L33: LILY/KYLE | M33: CAPGEMENI | N33: REACT
B34: =B33+1 -> 31 | C34: Models-User | D34: 45971 | E34: NO | F34: 1 | H34: BUSINESS | L34: LILY/KYLE | M34: CAPGEMENI | N34: REACT
B35: =B34+1 -> 32 | C35: Models-Review | D35: 45971 | E35: NO | F35: 1 | H35: BUSINESS | L35: LILY/KYLE | M35: CAPGEMENI | N35: REACT
B36: =B35+1 -> 33 | C36: Models-Park | D36: 45971 | E36: NO | F36: 1 | H36: BUSINESS | L36: LILY/KYLE | M36: CAPGEMENI | N36: REACT | O36: 3
B37: =COUNT(B3:B36) -> 34 | E37: =COUNT(E3:E36) -> 0 | F37: =COUNT(F12:F36) -> 25 | G37: =SUM(G3:G36) -> 8

Sheet UIIONIC
C2: TECHNOLOGY CONTRIBUTION | D2: Date | E2: REQUIREDS1 | F2: REQUIREDS2 | G2: RUBRICEXTRA | H2: TYPE1 | I2: TYPE2 | J2: DISCUSSION | K2: ORIGIN | L2: DEVELOPER | M2: TEAM | N2: CODETYPE
B3: 1 | C3: TAB1.tsx | D3: 45971 | E3: NO | F3: 0 | G3: 1 | H3: SALES | K3: NEW | L3: JSS | M3: 547G-T5 | N3: REACT
B4: =B3+1 -> 2 | C4: TAB2.tsx | D4: 45971 | E4: NO | F4: 0 | G4: 1 | H4: SALES | K4: NEW | L4: JSS | M4: 547G-T5 | N4: REACT
B5: =B4+1 -> 3 | C5: TAB3.tsx | D5: 45971 | E5: NO | F5: 0 | G5: 1 | H5: SALES | K5: NEW | L5: JSS | M5: 547G-T5 | N5: REACT
B6: =B5+1 -> 4 | C6: TAB4.tsx | D6: 45971 | E6: NO | F6: 0 | G6: 1 | H6: SSO | K6: NEW | L6: JSS | M6: 547G-T5 | N6: REACT
B7: =B6+1 -> 5 | C7: TAB5.tsx | D7: 45971 | E7: NO | F7: 0 | G7: 1 | H7: SSO | K7: NEW | L7: JSS | M7: 547G-T5 | N7: REACT
B8: =B7+1 -> 6 | C8: TAB6.tsx | D8: 45971 | E8: NO | F8: 0 | G8: 1 | H8: SSO | K8: NEW | L8: JSS | M8: 547G-T5 | N8: REACT
B9: =B8+1 -> 7 | C9: TAB7.tsx | D9: 45971 | E9: NO | F9: 0 | G9: 1 | H9: PARKMGR | K9: NEW | L9: JSS | M9: 547G-T5 | N9: REACT
B10: =B9+1 -> 8 | C10: TAB8.tsx | D10: 45971 | E10: NO | F10: 0 | G10: 1 | H10: SECURITY | K10: NEW | L10: JSS | M10: 547G-T5 | N10: REACT
B11: 9 | C11: menu.tsx | D11: 45971 | E11: NO | F11: 0 | G11: 1 | H11: SALES | K11: NEW | L11: JSS | M11: 547G-T5 | N11: REACT
B12: =B11+1 -> 10 | C12: app.tsx | D12: 45971 | E12: NO | F12: 0 | G12: 1 | H12: SALES | K12: MOD | L12: JSS | M12: 547G-T5/CG JOINT | N12: REACT
B13: =B12+1 -> 11 | C13: footer.tsx | D13: 45971 | E13: NO | F13: 0 | G13: 1 | H13: SALES | K13: MOD | L13: JSS | M13: 547G-T5/CG JOINT | N13: REACT
B14: =COUNT(B3:B13) -> 11 | E14: =COUNT(E3:E13) -> 0 | F14: 0 | G14: =SUM(G3:G13) -> 11

Sheet UIMANAGEROTHER
C2: TECHNOLOGY CONTRIBUTION | D2: Date | E2: REQUIREDS1 | F2: REQUIREDS2 | G2: RUBRICEXTRA | H2: TYPE1 | I2: TYPE2 | J2: DISCUSSION | K2: ORIGIN | L2: DEVELOPER | M2: TEAM | N2: CODETYPE
B3: 1 | C3: usermanager | D3: 46001 | E3: 0 | F3: 0 | G3: 1 | H3: SALES | L3: JSS | M3: 547G-T5 | N3: HTMLUI
B4: =B3+1 -> 2 | C4: employeemanager | D4: 46001 | E4: 0 | F4: 0 | G4: 1 | H4: SALES | L4: JSS | M4: 547G-T5 | N4: HTMLUI
B5: =B4+1 -> 3 | C5: parksmanager | D5: 46001 | E5: 1 | F5: 0 | G5: 0 | H5: CARE | L5: JSS | M5: 547G-T5 | N5: HTMLUI
B6: =B5+1 -> 4 | C6: securitycenter.html | D6: 46001 | E6: 0 | F6: 0 | G6: 1 | H6: SALES | L6: JSS | M6: 547G-T5 | N6: HTMLUI
B7: =B6+1 -> 5 | C7: securityreport.html by category | D7: 46001 | E7: 0 | F7: 0 | G7: 1 | H7: SALES | L7: JSS | M7: 547G-T5 | N7: HTMLUI
B8: =B7+1 -> 6 | C8: portalmanager.html | D8: 46001 | E8: 0 | F8: 0 | G8: 1 | H8: SALES | L8: JSS | M8: 547G-T5 | N8: HTMLUI
B9: =B8+1 -> 7 | C9: transactionreport.html | D9: 46001 | E9: 0 | F9: 0 | G9: 1 | H9: PARKMGR | L9: JSS | M9: 547G-T5 | N9: HTMLUI
B10: =B9+1 -> 8 | C10: bookingreport.html | D10: 46001 | E10: 0 | F10: 0 | G10: 1 | H10: SALES | L10: JSS | M10: 547G-T5 | N10: HTMLUI
B11: 9 | C11: transactionadmin.html | D11: 46001 | E11: 0 | F11: 0 | G11: 1 | H11: SALES | L11: JSS | M11: 547G-T5 | N11: HTMLUI
B12: 10 | C12: creditadmin.html | D12: 46001 | E12: 0 | F12: 0 | G12: 1 | H12: PARKMGR | L12: JSS | M12: 547G-T5 | N12: HTMLUI
B13: =B12+1 -> 11 | C13: ticketadmin.html | D13: 46001 | E13: 0 | F13: 0 | G13: 1 | H13: SALES | L13: JSS | M13: 547G-T5 | N13: HTMLUI
B14: =B13+1 -> 12 | C14: bookingadmin | D14: 46001 | E14: 0 | F14: 0 | G14: 1 | H14: CARE | L14: JSS | M14: 547G-T5 | N14: HTMLUI
B15: =B14+1 -> 13 | C15: salescatalogue | D15: 46001 | E15: 1 | F15: 0 | G15: 0 | H15: SALES | L15: JSS | M15: 547G-T5 | N15: HTMLUI
B16: =B15+1 -> 14 | C16: taxadministrator | D16: 46001 | E16: 0 | F16: 0 | G16: 1 | H16: CARE | L16: JSS | M16: 547G-T5 | N16: HTMLUI
B17: =B16+1 -> 15 | C17: salescatalogue report | D17: 46001 | E17: 0 | F17: 0 | G17: 1 | H17: CARE | L17: JSS | M17: 547G-T5 | N17: HTMLUI
B18: =B17+1 -> 16 | C18: erp batches | D18: 46001 | E18: 0 | F18: 0 | G18: 1 | H18: SALES | L18: JSS | M18: 547G-T5 | N18: HTMLUI | O18: =COUNT(B3:B18) -> 16
B19: =B18+1 -> 17 | C19: selector-bar - under construction | D19: 46001 | E19: 0 | F19: 0 | G19: 1 | H19: SECURITY | L19: JSS | M19: 547G-T5 | N19: HTMLUI
B20: 19 | C20: homepage by state | D20: 46001 | E20: 0 | F20: 0 | G20: 1 | H20: SSO | L20: JSS | M20: 547G-T5 | N20: HTMLUI
B21: 20 | C21: userprofile | D21: 46001 | E21: 0 | F21: 0 | G21: 1 | H21: SSO | L21: JSS | M21: 547G-T5 | N21: HTMLUI
B22: 21 | C22: saveminmal | D22: 46001 | E22: 0 | F22: 0 | G22: 1 | H22: SSO | L22: JSS | M22: 547G-T5 | N22: HTMLUI
B23: 22 | C23: saveextended | D23: 46001 | E23: 0 | F23: 0 | G23: 1 | H23: SSO | L23: JSS | M23: 547G-T5 | N23: HTMLUI
B24: 23 | C24: profileupload | D24: 46001 | E24: 0 | F24: 0 | G24: 1 | H24: SSO | L24: JSS | M24: 547G-T5 | N24: HTMLUI
B25: 24 | C25: profileaccounts | D25: 46001 | E25: 0 | F25: 0 | G25: 1 | H25: SSO | L25: JSS | M25: 547G-T5 | N25: HTMLUI
B26: 25 | C26: changepassword | D26: 46001 | E26: 0 | F26: 0 | G26: 1 | H26: SSO | L26: JSS | M26: 547G-T5 | N26: HTMLUI
B27: 25 | E27: =SUM(E3:E20) -> 2 | F27: =SUM(F3:F20) -> 0 | G27: =SUM(G3:G26) -> 22

Sheet BackOfficeBreakout
C2: EP Code By Contributor - Group
C3: USC GhostSquad | D3: =ControllersLogicByType!L35 -> 11 | E3: =D3/$D$6 -> 0.33333333
C4: 547G-TEAM5 (NEW) | D4: =ControllersLogicByType!L16 -> 14 | E4: =D4/$D$6 -> 0.42424242
C5: GS/547G MIX | D5: =ControllersLogicByType!L24 -> 8 | E5: =D5/$D$6 -> 0.24242424
C6: TOTAL ENDPOINTS | D6: =ControllersLogicByType!M36 -> 33 | E6: =D6/$D$6 -> 1
C9: EP Code By Contributor - Author
C10: JSS | D10: 32 | E10: =D10/$D$6 -> 0.96969697
C11: K.Baugh | D11: 1 | E11: =D11/$D$6 -> 0.03030303
C12: Ghost Team Other | D12: =ControllersLogicByType!L31 -> 0 | E12: =D12/$D$6 -> 0
C13: TOTAL ENDPOINTS | D13: 33 | E13: =D13/$D$6 -> 1
C16: Code Aging
C17: New Code | D17: 14 | E17: =D17/$D$6 -> 0.42424242
C18: Upgraded Code | D18: 8 | E18: =D18/$D$6 -> 0.24242424
C19: Ghost Squad S2025 | D19: =D3 -> 11 | E19: =D19/$D$6 -> 0.33333333
C20: TOTAL ENDPOINTS | D20: 33 | E20: =D20/$D$6 -> 1
C23: Rubrick Required Endpoints vs Additional
C24: Description | D24: Eps | F24: Variance
C25: Required Totals | D25: =ControllersLogicByType!M42 -> 8
C26: Extra Credit | D26: 3
C27: Ghost Squad Unchanged | D27: =ControllersLogicByType!L35 -> 11
C28: Jss New | D28: =D4 -> 14 | F28: =(D28-D25)/D25 -> 0.75
C29: Jss Upgraded | D29: =ControllersLogicByType!L24 -> 8 | F29: 0
C30: Jss New and Upgraded | D30: =22 -> 22 | F30: =(D30-D25)/D25 -> 1.75
C31: Full Team5 EPS w GS | D31: 33 | F31: =(D31-D25)/D25 -> 3.125
C32: Reused Code | D32: =19 -> 19 | F32: =D32/D33 -> 0.57575758
C33: TOTAL ENDPOINTS | D33: 33 | F33: =D33/$D$6 -> 1

Sheet FrontOfficeBreakout
C2: HTML FILES BY GROUP
C3: USC GhostSquad | D3: 6 | E3: =D3/$D$6 -> 0.2 | H3: THIS HASNT BEEN UPDATED YET
C4: 547G-TEAM5 (NEW) | D4: 18 | E4: =D4/$D$6 -> 0.6
C5: GS/547G MIX | D5: 6 | E5: =D5/$D$6 -> 0.2
C6: TOTAL HTML FILES | D6: 30 | E6: =D6/$D$6 -> 1
C9: HTML FILES BY AUTHOR
C10: JSS | D10: 25 | E10: =D10/$D$6 -> 0.83333333
C11: Pranavi | D11: 3 | E11: =D11/$D$6 -> 0.1
C12: Carolina | D12: 1 | E12: =D12/D14 -> 0.033333333
C13: Ghost Team Other Or Mix | D13: 1 | E13: =D13/$D$6 -> 0.033333333
C14: TOTAL FILES IN SCOPE MAJOR | D14: 30 | E14: =D14/$D$6 -> 1
C17: Code Aging
C18: New Code | D18: 18 | E18: =D18/$D$6 -> 0.6
C19: Upgraded Code | D19: 6 | E19: =D19/$D$6 -> 0.2
C20: Ghost Squad S2025 | D20: =D3 -> 6 | E20: =D20/$D$6 -> 0.2
C21: TOTAL FILES IN SCOPE MAJOR | D21: 30 | E21: =D21/$D$6 -> 1
C24: Rubrick Required UI vs Additional
C25: Description | D25: HTML FIles | F25: %
C26: Required Totals | D26: 27 | F26: =D26/D34 -> 0.9
C27: Extra Credit | D27: 3
C28: Ghost Squad Unchanged | D28: 6 | F28: =D28/D34 -> 0.2
C29: Jss New | D29: =D4 -> 18 | F29: =D29/D34 -> 0.6
C30: Jss Upgraded | D30: 6 | F30: =D30/D34 -> 0.2
C31: Jss New and Upgraded | D31: 24 | F31: =D31/D34 -> 0.8
C32: Full Team5 HTML w GS | D32: 30 | F32: =D32/D34 -> 1
C33: Reused Code | D33: 12 | F33: =D33/D34 -> 0.4
C34: TOTAL FILES IN SCOPE MAJOR | D34: 30 | F34: =D34/$D$6 -> 1

Sheet LSINFO
D1: 2025/11/01 - 01:26:52
C2: adminerror.html | D2: 2025/11/01 - 17:55:49 | H2: adminerror.html | J2: 2025/11/01 - 01:26:52
C3: adminhome.html | D3: 2025/11/06 - 17:43:05 | H3: adminhome.html | J3: 2025/11/01 - 17:55:49
C4: book5.html | D4: 2025/11/01 - 21:48:08 | H4: book5.html | J4: 2025/11/06 - 17:43:05
C5: cart5.html | D5: 2025/10/25 - 04:53:01 | H5: cart5.html | J5: 2025/11/01 - 21:48:08
C6: cartcancel.html | D6: 2025/11/01 - 23:23:19 | H6: cartcancel.html | J6: 2025/10/25 - 04:53:01
C7: cartdetail.html | D7: 2025/10/24 - 16:56:51 | H7: cartdetail.html | J7: 2025/11/01 - 23:23:19
C8: cartdetail2b.html | D8: 2025/11/06 - 17:43:32 | H8: cartdetail2b.html | J8: 2025/10/24 - 16:56:51
C9: cartreview.html | D9: 2025/11/06 - 15:26:18 | H9: cartreview.html | J9: 2025/11/06 - 17:43:32
C10: employeemaint.html | D10: 2025/10/25 - 04:54:02 | H10: employeemaint.html | J10: 2025/11/06 - 15:26:18
C11: findpark.html | D11: 2025/10/25 - 04:57:05 | H11: findpark.html | J11: 2025/10/25 - 04:54:02
C12: help.html | D12: 2025/10/24 - 17:17:58 | H12: help.html | J12: 2025/10/25 - 04:57:05
C13: images/applications.html | D13: 2025/10/24 - 17:18:03 | H13: images/applications.html | J13: 2025/10/24 - 17:17:58
... C30: picturewall.html | D30: 2025/10/26 - 17:36:57 | H30: picturewall.html | J30: 2025/10/26 - 17:36:57

Sheet AllEndpointsDetail-S1
C2: Adminlog
C3: GET
C4: /api/Adminlogs
C5: POST
C6: /api/Adminlogs
C7: GET
C8: /api/Adminlogs/{id}
C9: PUT
C10: /api/Adminlogs/{id}
C11: DELETE
C12: /api/Adminlogs/{id}
C13: Apilog
... C366: /WeatherForecast
